<?xml version="1.0"?>

<robot
xmlns:sensor="http://playerstage.sourceforge.net/gazebo/xmlschema/#sensor"
xmlns:controller="http://playerstage.sourceforge.net/gazebo/xmlschema/#controller"
xmlns:interface="http://playerstage.sourceforge.net/gazebo/xmlschema/#interface"
  xmlns:xacro="http://playerstage.sourceforge.net/gazebo/xmlschema/#interface">
    
    <include filename="$(find hector_sensors_description)/urdf/hokuyo_utm30lx.urdf.xacro" />
    
    <!-- Properties (Constants) -->
    <xacro:property name="M_PI" value="3.14159" />
    
    <xacro:macro name="sensor_roll_pitch_mount" params="parent prefix offset_x offset_y offset_z">
        
        <joint name="${prefix}_roll_pitch_mount" type="fixed">
            <origin xyz="${offset_x } ${offset_y} ${offset_z}" rpy="0 0 0" />
            <parent link="${parent}" />
            <child link="${prefix}_base_link" />
            <!--<mimic joint="steer${prefix}" multiplier="1.234" offset="0.0" />-->
        </joint>
        
        <joint name="${prefix}_roll_joint" type="revolute">
            <parent link="${prefix}_base_link"/>
            <child link="${prefix}_rolled_link"/>
            <origin xyz="0 0 0.1" rpy="0 0 0" />
             
            <axis xyz="-1 0 0" />
            	
            <limit  lower="-1.5708" upper="1.5708" effort="1.0" velocity="1.5708" />
            <!--	<safety_controller k_position="0.1" k_velocity="1.0" soft_lower_limit="${-1.5708+0.1}" soft_upper_limit="${1.5708-0.1}" />-->
            <dynamics damping="0.01" friction="0.01"/>
        </joint>
        
        <joint name="${prefix}_pitch_joint" type="revolute">
            <parent link="${prefix}_rolled_link"/>
            <child link="${prefix}_pitched_link"/>
            <origin xyz="0 0 0.02" rpy="0 0 0" />
            <axis xyz="0 -1 0" />
            	
            <limit  lower="-1.5708" upper="1.5708" effort="1.0" velocity="1.5708" />
            <!--	<safety_controller k_position="0.1" k_velocity="1.0" soft_lower_limit="${-1.5708+0.1}" soft_upper_limit="${1.5708-0.1}" />-->
            <dynamics damping="0.01" friction="0.01"/>
            	
        </joint>
        
        <link name="${prefix}_base_link">
            <inertial>
                <mass value="0.1" />
                <origin xyz="0.0 0.0 0.0" rpy="0 0 0" />
                <inertia ixx="0.0001" ixy="0.0" ixz="0.0"
	  iyy="0.0001" iyz="0.0" 
	    izz="0.0001" />
            </inertial>
            
            <visual>
                <origin xyz="0.0 0.0 0.05" rpy="0 0 0" />
                <geometry>
                    <box size="0.02 0.02 0.08" />
                </geometry>
                <material name="Grey" >
                    <color rgba="0.8 0.8 0.8 1"/>
                </material>
                
            </visual>
            
            <collision>
                <origin xyz="0.0 0.0 0.05" rpy="0 0 0" />
                <geometry>
                    <box size="0.02 0.02 0.08" />
                </geometry>
            </collision>
        </link>
        
        <link name="${prefix}_rolled_link">
            <inertial>
                <mass value="0.1" />
                <origin xyz="0.0 0.0 0.0" rpy="0 0 0" />
                <inertia ixx="0.0001" ixy="0.0" ixz="0.0"
	    iyy="0.0001" iyz="0.0" 
	      izz="0.0001" />
            </inertial>
            
            <visual>
                <origin xyz="0.0 0.0 0.01" rpy="0 0 0" />
                <geometry>
                    <box size="0.02 0.02 0.02" />
                </geometry>
                <material name="Grey" >
                    <color rgba="0.8 0.8 0.8 1"/>
                </material>
                
            </visual>
            
            <collision>
                <origin xyz="0.0 0.0 0.01" rpy="0 0 0" />
                <geometry>
                    <box size="0.02 0.02 0.02" />
                </geometry>
            </collision>
        </link>
        
        <link name="${prefix}_pitched_link">
            <inertial>
                <mass value="0.1" />
                <origin xyz="0.0 0.0 0.0" rpy="0 0 0" />
                <inertia ixx="0.0001" ixy="0.0" ixz="0.0"
	      iyy="0.0001" iyz="0.0" 
		izz="0.0001" />
            </inertial>
            
            <visual>
                <origin xyz="0.0 0.0 0.01" rpy="0 0 0" />
                <geometry>
                    <box size="0.02 0.02 0.02" />
                </geometry>
                <material name="Grey" >
                    <color rgba="0.8 0.8 0.8 1"/>
                </material>
                
            </visual>
            
            <collision>
                <origin xyz="0.0 0.0 0.01" rpy="0 0 0" />
                <geometry>
                    <box size="0.02 0.02 0.02" />
                </geometry>
            </collision>
        </link>
        
        
        
        <transmission type="pr2_mechanism_model/SimpleTransmission" name="${prefix}_roll_trans">
            <actuator name="${prefix}_roll_motor" />
            <joint name="${prefix}_roll_joint" />
            <mechanicalReduction>1.0</mechanicalReduction>
        </transmission>
        
        <transmission type="pr2_mechanism_model/SimpleTransmission" name="${prefix}_pitch_trans">
            <actuator name="${prefix}_pitch_motor" />
            <joint name="${prefix}_pitch_joint" />
            <mechanicalReduction>1.0</mechanicalReduction>
        </transmission>
        
        
        <gazebo reference="${prefix}_base_link">
            <material>Gazebo/Red</material>
            <turnGravityOff>true</turnGravityOff>	    
        </gazebo>
        
        <gazebo reference="${prefix}_rolled_link">
            <material>Gazebo/Red</material>
            <turnGravityOff>true</turnGravityOff>
        </gazebo>
        
        <gazebo reference="${prefix}_pitched_link">
            <material>Gazebo/Red</material>
            <turnGravityOff>true</turnGravityOff>
        </gazebo>
        
        
        <xacro:hokuyo_utm30lx name="laser1" parent="${prefix}_pitched_link" ros_topic="laser1/scan" update_rate="40" ray_count="1081" min_angle="135" max_angle="-135">
            <origin xyz="0 0 0" rpy="0 0 0"/>
        </xacro:hokuyo_utm30lx>
        
        
        <!-- This adds a visual box to allow us to see the Hokuyo in rviz/gazebo -->
<!--        <joint name="sim300_joint" type="fixed">
            <origin xyz="0 0 0" rpy="0 0 0" />
            <parent link="${prefix}_pitched_link" />
            <child link="sim300_link"/>
        </joint>
        <link name="sim300_link">
            <inertial>
                <mass value="0.00" />
                <origin xyz="0 0 0" />
                <inertia ixx="0.001"  ixy="0.0"  ixz="0.0"
               iyy="0.001"  iyz="0.0"
               izz="0.001" />
            </inertial>
            <visual>
                <origin xyz="0 0 0" rpy="0 0 0"/>
                <geometry>
                    <box size="0.05 0.05 0.1" />
                </geometry>
            </visual>
            <collision>
                <origin xyz="0 0 0" rpy="0 0 0"/>
                <geometry>
                    <box size="0.05 0.05 0.1" />
                </geometry>
            </collision>
        </link>-->
                
    </xacro:macro>
</robot>

